package org.example;
import junit.framework.Test;
import junit.framework.TestCase;



public class CalculatorAppTest extends TestCase {
    private CalculatorApp calc;
    @Override
    protected void setUp() throws Exception {
        super.setUp();
        calc = new CalculatorApp();
    }
    private void testAssertEqualsSum(Double a, Double b, Double expected) {
        assertEquals(expected, calc.sum(a, b));
    }
    private void testAssertEqualsSub(Double a, Double b, Double expected) {
        assertEquals(expected, calc.sub(a, b));
    }

    private void testAssertEqualsMulti(Double a, Double b, Double expected) {
        assertEquals(expected, calc.mul(a, b));
    }
    private void testAssertEqualsDiv(Double a, Double b, Double expected) {
        assertEquals(expected, calc.div(a, b));
    }

    public void testSum(){
        testAssertEqualsSum(2.0, 2.0, 4.0);
    }
    public void testSub(){
        testAssertEqualsSub(2.0, 2.0, 0.0);
    }
    public void testMulti(){
        testAssertEqualsMulti(2.0, 2.0, 4.0);
    }
    public void testDiv(){
        testAssertEqualsDiv(4.0, 2.0, 2.0);
    }
    public void testDivByZero() {
        try {
            calc.div(4.0, 0.0); // Ожидается ArithmeticException
            fail("Expected ArithmeticException to be thrown");
        } catch (ArithmeticException e) {
            // Успешный тест, исключение выброшено
        }
    }
}
